Workbook

Sheet Macrocicle
A1: Planificació Primer Macrocicle 2026-27 — Jep
A2: Proves objectiu A: 50 Papallona, 100 Lliure, 100 Estils
A3: Sprint de papallona + mig-fons de lliure + estils. Prioritat: base aeròbica sòlida + especificitat en fatiga.
A4: 21/09/2026 - 07/02/2027 | Objectiu final: Campionat Catalunya Hivern + Campeonato España Invierno (doble pic)
A6: Mesocicle | B6: Setmanes | C6: Dates | D6: Fase / Objectiu | E6: Metodologia dominant | F6: Volum setmanal (rang) | G6: Volum mitjà previst (m) | H6: Tancament (control/objectiu)
A7: M1 - Base | B7: 1-4 | C7: 21/09 - 18/10/2026 | D7: Base aeròbica general i tècnica. Familiarització amb el test CSS. | E7: Escola Australiana (volum, base aeròbica alta, tècnica crol i papallona). | F7: 15.500 - 17.000 m | G7: =ROUND(AVERAGEIF(Microcicles!$C$3:$C$22,"M1",Microcicles!$E$3:$E$22),0) -> 15500 | H7: Control B: Etapa Barceloneta (17/10)
A8: M2 - Desenvolupament I | B8: 5-7 | C8: 19/10 - 08/11/2026 | D8: Consolidació aeròbica i introducció de treball llindar/ritme de cursa. | E8: Australiana + llindar aeròbic. Introducció de ritme de cursa al 50 Papallona. | F8: 13.000 - 15.500 m | G8: =ROUND(AVERAGEIF(Microcicles!$C$3:$C$22,"M2",Microcicles!$E$3:$E$22),0) -> 14500 | H8: Control B: Memorial Cuesta (07/11)
A9: M3 - Desenvolupament II / Construcció | B9: 8-12 | C9: 09/11 - 13/12/2026 | D9: Construcció específica: augment de treball a ritme de cursa i qualitat. | E9: Bowman (main sets que simulen la 2a meitat del 100 Lliure) + USRPT per al 50 Pap. | F9: 13.000 - 15.500 m | G9: =ROUND(AVERAGEIF(Microcicles!$C$3:$C$22,"M3",Microcicles!$E$3:$E$22),0) -> 14600 | H9: Control C: Gran Premi Marrugat (12/12)
A10: M4 - Específic / Pre-competitiu | B10: 13-16 | C10: 14/12/2026 - 10/01/2027 | D10: Treball específic de ritme de cursa; descàrrega activa a Nadal/Cap d'Any; test intern de comprovació. | E10: Bowman (simulació de fatiga de cursa 100 Lliure) + USRPT (ritme exacte 50 Pap). | F10: 12.000 - 14.000 m | G10: =ROUND(AVERAGEIF(Microcicles!$C$3:$C$22,"M4",Microcicles!$E$3:$E$22),0) -> 13000 | H10: Test intern d'avaluació (setmana 16)
A11: M5 - Competitiu / Doble Pic | B11: 17-20 | C11: 11/01 - 07/02/2027 | D11: Doble taper: Campionat Catalunya (pic 1) i Campeonato España (pic 2), amb re-càrrega breu entremig. | E11: Taper: manteniment del ritme de cursa, reducció de volum. | F11: 12.000 - 13.500 m | G11: =ROUND(AVERAGEIF(Microcicles!$C$3:$C$22,"M5",Microcicles!$E$3:$E$22),0) -> 12750 | H11: Objectiu A: Campionat Catalunya + Campeonato España
A13: Volum mitjà de tot el macrocicle (m): | B13: =ROUND(AVERAGE(Microcicles!$E$3:$E$22),0) -> 14075
A14: Nombre de setmanes de qualitat (Dc+Ds): | B14: =COUNTIF(Microcicles!$F$3:$F$22,"Sí") -> 4
A15: Nombre de setmanes amb competició/test oficial: | B15: =COUNTIF(Microcicles!$H$3:$H$22,"<>-") -> 6

Sheet Microcicles
A1: Planificació setmana a setmana — Jep
A2: Setmana | B2: Dates | C2: Meso | D2: Tipus de setmana | E2: Volum objectiu (m) | F2: Dies qualitat (Dc+Ds) | G2: Test CSS (repetició 6-8 set.) | H2: Competició / Test oficial | I2: Test avaluació d'assoliment | J2: Focus específic — Jep
A3: 1 | B3: 21-27/09/2026 | C3: M1 | D3: Càrrega + Test CSS | E3: 16000 | F3: No | G3: Test CSS #1 (Dijous 24/09/2026) - línia base | H3: Test CSS - Dijous 24/09/2026 (determina zones A1/A2/A3) | I3: - | J3: Base aeròbica alta (Australiana). Tècnica crol i papallona. Test CSS dijous.
A4: 2 | B4: 28/09-04/10/2026 | C4: M1 | D4: Càrrega | E4: 16500 | F4: No | G4: - | H4: - | I4: - | J4: Consolidació aeròbica. Volum de crol per a base del 100 Lliure.
A5: 3 | B5: 05-11/10/2026 | C5: M1 | D5: Qualitat (Dc + Ds) | E5: 16000 | F5: Sí | G5: - | H5: - | I5: - | J5: Qualitat: llindar aeròbic + introducció ritme 50 Pap.
A6: 4 | B6: 12-18/10/2026 | C6: M1 | D6: Descàrrega + Competició Control B | E6: 13500 | F6: No | G6: - | H6: Etapa Barceloneta - Dissabte 17/10/2026 (Classe B) | I6: Control extern (resultat de la cursa) | J6: Descàrrega + Etapa Barceloneta com a control (100 Lliure / 50 Pap).
A7: 5 | B7: 19-25/10/2026 | C7: M2 | D7: Càrrega | E7: 15500 | F7: No | G7: - | H7: - | I7: - | J7: Represa de càrrega aeròbica.
A8: 6 | B8: 26/10-01/11/2026 | C8: M2 | D8: Qualitat (Dc + Ds) | E8: 15000 | F8: Sí | G8: - | H8: - | I8: - | J8: Qualitat: sèries a ritme de cursa 50 Pap + resistència a la velocitat 100 Lliure.
A9: 7 | B9: 02-08/11/2026 | C9: M2 | D9: Descàrrega + Competició Control B + Test CSS | E9: 13000 | F9: No | G9: Test CSS #2 (Dijous, +6 set.) - recalibratge previ a M3 | H9: Memorial Cuesta - Dissabte 07/11/2026 (Classe B) | I9: Control extern (resultat de la cursa) | J9: Descàrrega + Memorial Cuesta com a control.
A10: 8 | B10: 09-15/11/2026 | C10: M3 | D10: Càrrega | E10: 15000 | F10: No | G10: - | H10: - | I10: - | J10: Construcció: main sets Bowman (100 Lliure amb fatiga simulada).
A11: 9 | B11: 16-22/11/2026 | C11: M3 | D11: Càrrega | E11: 15500 | F11: No | G11: - | H11: - | I11: - | J11: Construcció: consolidació ritme 50 Pap + IM.
A12: 10 | B12: 23-29/11/2026 | C12: M3 | D12: Qualitat (Dc + Ds) | E12: 15000 | F12: Sí | G12: - | H12: - | I12: - | J12: Qualitat: USRPT 50 Pap + sèries llindar 100 Lliure.
A13: 11 | B13: 30/11-06/12/2026 | C13: M3 | D13: Càrrega (transició) | E13: 14500 | F13: No | G13: - | H13: - | I13: - | J13: Transició cap al control C: reducció progressiva de volum.
A14: 12 | B14: 07-13/12/2026 | C14: M3 | D14: Descàrrega + Competició Control C | E14: 13000 | F14: No | G14: - | H14: Gran Premi Marrugat - Dissabte 12/12/2026 (Classe C) | I14: Control extern (resultat de la cursa) | J14: Descàrrega + Gran Premi Marrugat com a control (100 Lliure / 50 Pap).
... A22: 20 | B22: 01-07/02/2027 | C22: M5 | D22: Taper final + Competició A (Pic 2) | E22: 12000 | F22: No | G22: - | H22: Campeonato España Invierno - 04-07/02/2027 (Classe A) | I22: - | J22: Taper final: Campeonato España - objectiu 50 Pap / 100 Lliure / 100 IM.

Sheet Sept
A1: Setembre 2026 — Jep
A2: Setmana 1 (21-27/09/2026) — Mesocicle M1, setmana de Càrrega + Test CSS (dijous)
A4: Setmana 1
A5: Dia | B5: Treball | C5: Execució | D5: Descans | E5: Material | F5: Intensitat | H5: Objectiu | I5: Temps (min) | J5: Volum (m)
A6: Dilluns 21/09 | B6: 400 | C6: Crol suau + Ei | D6: - | E6: - | F6: A1 | H6: Escalfament | I6: 8 | J6: 400
B7: 8x50 | C7: Crol amb Pales petites (focus captura / colze alt) | D7: c/1' | E7: Pales petites | F7: A1 | H7: Tècnica captura Crol | I7: 8 | J7: 400
B8: 6x25 | C8: Subaquàtic Crol: sortida + primeres braçades | D8: c/45" | E8: Aletes | F8: Tècnica | H8: Subaquàtic Crol (5è estil) | I8: 3 | J8: 150
B9: 10x200 | C9: Crol r/4 | D9: c/3'15" | E9: - | F9: A1 | H9: Aeròbic Crol | I9: 40 | J9: 2000
B10: 6x50 | C10: Papallona suau (introducció tècnica) | D10: c/1'15" | E10: Pull-buoy | F10: A1 | H10: Tècnica base Papallona | I10: 6 | J10: 300
B11: 300 | C11: Ei suau | D11: - | E11: - | F11: A0 | H11: Tornada a la calma | I11: 6 | J11: 300
B12: Total | I12: =SUM(I6:I11) -> 71 | J12: =SUM(J6:J11) -> 3550
A14: Dimarts 22/09 | B14: 300 | C14: Crol + Esquena suau | D14: - | E14: - | F14: A1 | H14: Escalfament | I14: 6 | J14: 300
B15: 8x50 | C15: Crol amb Aletes (ritme i patada) | D15: c/1' | E15: Aletes | F15: A1 | H15: Eficiència Crol | I15: 8 | J15: 400
B16: 4x50 | C16: Sortida + 15m subaquàtic Crol | D16: c/1' | E16: Aletes | F16: Tècnica | H16: Subaquàtic / Sortides | I16: 4 | J16: 200
B17: 14x100 | C17: Crol r/4 (2 A1 + 1 A2 rotatiu) | D17: c/1'50" | E17: - | F17: A1/A2 | H17: Aeròbic Crol | I17: 28 | J17: 1400
B18: 6x50 | C18: Papallona tècnica (Pull-buoy) | D18: c/1'15" | E18: Pull-buoy | F18: A1 | H18: Tècnica Papallona | I18: 6 | J18: 300
B19: 300 | C19: Ei suau | D19: - | E19: - | F19: A0 | H19: Tornada a la calma | I19: 6 | J19: 300
B20: Total | I20: =SUM(I14:I19) -> 58 | J20: =SUM(J14:J19) -> 2900
A22: Dimecres 23/09 | B22: 400 | C22: Crol + Ei | D22: - | E22: - | F22: A1 | H22: Escalfament | I22: 8 | J22: 400
B23: 8x50 | C23: Crol amb Pales grans (força de braçada) | D23: c/1' | E23: Pales grans | F23: A2 | H23: Força específica Crol | I23: 8 | J23: 400
B24: 6x25 | C24: Subaquàtic Papallona (introducció ones) | D24: c/40" | E24: Aletes | F24: Tècnica | H24: Subaquàtic (5è estil) | I24: 3 | J24: 150
B25: 12x150 | C25: Crol r/3 | D25: c/2'30" | E25: Pull-buoy | F25: A1 | H25: Aeròbic Crol | I25: 36 | J25: 1800
B26: 6x50 | C26: Papallona A2 progressiu | D26: c/1'15" | E26: - | F26: A2 | H26: Qualitat aeròbica Papallona | I26: 6 | J26: 300
B27: 4x100 | C27: Estils (IM), ritme suau | D27: c/2' | E27: - | F27: A1 | H27: Tècnica canvis IM | I27: 8 | J27: 400
B28: 300 | C28: Ei suau | D28: - | E28: - | F28: A0 | H28: Tornada a la calma | I28: 6 | J28: 300
B29: Total | I29: =SUM(I22:I28) -> 75 | J29: =SUM(J22:J28) -> 3750
A31: Dijous 24/09 | B31: 600 | C31: Crol + Ei progressiu | D31: - | E31: - | F31: A1 | H31: Escalfament | I31: 12 | J31: 600
B32: 4x50 | C32: Activació progressiva cap a A3 | D32: c/1' | E32: - | F32: A2/A3 | H32: Activació pre-test | I32: 4 | J32: 200
B33: 400 | C33: TEST CSS (1/2): 400m Crol a MÀXIM esforç constant | D33: - | E33: - | F33: Màxim | H33: Test CSS - determina zones A1/A2/A3 | I33: 8 | J33: 400
B34: 200 | C34: Recuperació activa molt suau | D34: 15-20' pausa | E34: - | F34: A0 | H34: Recuperació entre els dos tests | I34: 4 | J34: 200
B35: 200 | C35: TEST CSS (2/2): 200m Crol a MÀXIM esforç constant | D35: - | E35: - | F35: Màxim | H35: Test CSS - determina zones A1/A2/A3 | I35: 4 | J35: 200
B36: 4x50 | C36: Nado suau (estil objectiu), tècnica/relaxació | D36: c/1'15" | E36: - | F36: A1 | H36: Tornada tècnica | I36: 4 | J36: 200
B37: 300 | C37: Ei suau + estirament a l'aigua | D37: - | E37: - | F37: A0 | H37: Tornada a la calma | I37: 6 | J37: 300
B38: Total | I38: =SUM(I31:I37) -> 42 | J38: =SUM(J31:J37) -> 2100
A40: Divendres 25/09 | B40: - | C40: Descans total | D40: - | E40: - | F40: - | H40: Descans | I40: 0 | J40: 0
B41: Total | I41: =SUM(I40) -> 0 | J41: =SUM(J40) -> 0
A43: Dissabte 26/09 | B43: 300 | C43: Crol suau | D43: - | E43: - | F43: A1 | H43: Escalfament | I43: 6 | J43: 300
B44: 8x50 | C44: Crol tècnica (Pull-buoy) | D44: c/1' | E44: Pull-buoy | F44: A1 | H44: Tècnica manteniment | I44: 8 | J44: 400
B45: 10x100 | C45: Crol r/4 aeròbic | D45: c/1'50" | E45: - | F45: A1 | H45: Aeròbic manteniment | I45: 20 | J45: 1000
B46: 4x50 | C46: Papallona ritme lliure | D46: c/1'15" | E46: - | F46: A2 | H46: Manteniment específic | I46: 4 | J46: 200
...

Sheet Estructura de sessió
A1: Estructura de sessió — Jep
A2: 5 parts per sessió. El pes de cada part varia segons el tipus de setmana.
A4: Part de la sessió | B4: Contingut | C4: Setmana Càrrega | D4: Setmana Qualitat | E4: Descàrrega / Test
A5: Escalfament | B5: Aeròbic suau + mobilitat articular | C5: 10% | D5: 10% | E5: 15%
A6: Tècnica (inclou 5è estil: Subaquàtic) | B6: Drills per estil objectiu + sortides/viratges/patada subaquàtica | C6: 20% | D6: 15% | E6: 15%
A7: Aeròbic / Llindar | B7: Volum principal en zones A1/A2 | C7: 50% | D7: 30% | E7: 20%
A8: Específic / Qualitat | B8: Ritme de cursa (USRPT) o simulació de fatiga (Bowman), segons fase | C8: 10% | D8: 35% | E8: 40% (si és test)
A9: Tornada a la calma | B9: Recuperació activa, baixa intensitat | C9: 10% | D9: 10% | E9: 10%
A12: Material disponible i ús tècnic
A13: Material | B13: Ús tècnic principal
A14: Aletes | B14: Patada i subaquàtic: potència i amplitud de batuda
A15: Pales petites | B15: Sensibilitat i captura (agafar aigua)
A16: Pales grans | B16: Força específica de braçada
A17: Suro | B17: Aïllament de cames
A18: Pull-buoy | B18: Aïllament de braçada / focus de posició
A19: Tub | B19: Alineació postural i control respiratori
A22: Contingut de 'Tècnica (+ Subaquàtic)' i 'Específic/Qualitat' per mesocicle — Jep
A23: Mesocicle | B23: Tècnica (inclou 5è estil: Subaquàtic) + Material | C23: Específic / Qualitat (metodologia)
A24: M1 - Base | B24: Crol: captura/colze alt + Papallona bàsica + Subaquàtic crol. Material: Pales petites, Suro. | C24: Australiana: aeròbic de base.
A25: M2 - Desenvolupament I | B25: Crol: eficiència + Papallona: introducció ritme + Subaquàtic. Material: Pull-buoy, Aletes. | C25: Llindar aeròbic + inici de ritme de cursa al 50 Pap.
A26: M3 - Desenvolupament II / Construcció | B26: Crol: força final de braçada + Subaquàtic (viratges crol). Material: Pales grans, Aletes. | C26: Bowman (fatiga 100 Lliure) + USRPT (50 Pap).
A27: M4 - Específic / Pre-competitiu | B27: Manteniment crol/papallona en fatiga + Subaquàtic. Material: Tub, Pull-buoy. | C27: Bowman (simulació fatiga 100 Lliure) + USRPT (ritme exacte 50 Pap).
A28: M5 - Competitiu / Doble Pic | B28: Manteniment mínim. Material: Tub. | C28: Taper: manteniment de ritme de cursa.

Sheet Ritmes
A1: ="Taula de ritmes — " & B4 -> Taula de ritmes — Jep
A2: PLANTILLA GENÈRICA — mateixa estructura per a tots els nedadors, dades a la columna B. Font prioritària: Test CSS (si s'introdueixen B9/B10). Si no, s'usa el model de percentatge sobre la millor marca. Cel·les grogues = editar per cada nedador.
A3: DADES DEL NEDADOR
A4: Nom nedador | B4: Jep
A5: Edat | B5: 60
A6: Categoria | B6: master | C6: Literal: absolut / master / junior
A7: FONT 1 — TEST CSS (prioritària quan hi hagi dades)
A8: Data del test | C8: Deixa en blanc fins que hi hagi resultat.
A9: Temps 400m (s) | C9: Introdueix en segons (ex. 5'30"00 = 330).
A10: Temps 200m (s) | C10: Esforç màxim, mateixa sessió que el 400m (10-15 min de descans entremig).
A11: CSS — velocitat (m/s) | B11: =IF(AND(B9<>"",B10<>""),(400-200)/(B9-B10),"") | C11: Fórmula validada (Wakayoshi et al., 1992): (400-200)/(t400-t200).
A12: CSS — ritme per 100m (s) | B12: =IF(B11<>"",100/B11,"")
A14: FONT 2 — MILLOR MARCA DE COMPETICIÓ (fallback / contrast)
A15: Millor marca 100m lliures (s) | B15: 77.08 | C15: ( = 1'17"08, piscina 25m )
A16: Comprovació format | B16: =TEXT(INT(B15/60),"0")&"'"&TEXT(MOD(B15,60),"00.00")&"""""" -> 1'17.08""
A18: Altres millors marques (referència, no s'utilitzen al càlcul)
A19: 50m Papallona | B19: 38"86
A20: 50m Lliure (s) | B20: 33.44 | C20: ( = 33"44 ). Numèric i utilitzat com a àncora real de la zona Velocitat (font 2) — evita extrapolar un ritme més ràpid que la pròpia marca de 100m.
A21: 200m Lliure | B21: 3'03"00
A22: 100m IM | B22: 1'38"00
A24: PARÀMETRES DEL MODEL — Font 2 (ajustables, compartits per defecte)
A25: Increment A3 sobre marca | B25: 0.015
A26: Increment A2 sobre marca | B26: 0.065
A27: Increment A1 sobre marca | B27: 0.13
A28: Increment Recuperació sobre marca | B28: 0.2 | C28: Estimat — equival a ~115-130% del ritme de llindar (Maglischo, 2003, 'Swimming Fastest'). Ajustar si cal.
A29: Factor Velocitat sobre marca/CSS | B29: 0.85 | C29: Zona 5 (Maglischo, 2003): 75-90% del temps de llindar. S'aplica NOMÉS sobre CSS (llindar real). Amb font 'marca', la Velocitat s'ancora directament a la marca real de 50m (B20), no a un percentatge del 100m.
A30: Factor d'escala 50↔100m | B30: 2.02
A31: Factor d'escala 100↔200m | B31: 2.04
A32: Esquena: increment mínim | B32: 0.1
A33: Esquena: increment màxim | B33: 0.11
A34: Braça: increment mínim | B34: 0.15
A35: Braça: increment màxim | B35: 0.2
A37: PARÀMETRES DEL MODEL — Font 1, CSS (offsets validats) — Font: Maglischo, 2003, Swimming Fastest
A38: Offset Recuperació sobre CSS (s) | B38: 12
A39: Offset A1 sobre CSS (s) | B39: 6
A40: Offset A2 sobre CSS (s) [= llindar] | B40: 0
A41: Offset A3 sobre CSS (s) [VO2max] | B41: -4
A43: FONT ACTIVA
A44: Font utilitzada | B44: =IF(AND(B9<>"",B10<>""),"Test CSS ("&TEXT(B8,"dd/mm/yyyy")&")","Estimat per millor marca (provisional)") -> Estimat per millor marca (provisional)
A46: ZONES CALCULADES — Crol, ritme per 100m (segons)
...

Sheet Notes i supòsits
A1: Notes i supòsits d'aquesta planificació
A3: • Volum: rang uniforme de 12.000 a 17.000 m/setmana aplicat als 4 nedadors (indicat per l'usuari). Els valors setmanals d'aquest full són punts de partida i s'han d'ajustar amb el criteri de l'entrenador.
A4: • Ritmes de zona (A1/A2/A3): Lou i Jep tenen valors actuals (a actualitzar amb el test CSS). Cris i Pere parteixen d'estimació indirecta fins que facin el test CSS.
A5: • Test CSS: programat per a tots els nedadors el DIJOUS 24/09/2026 (setmana 1). Amb el resultat s'actualitzaran les zones A1/A2/A3 i, si la metodologia aplicada ho requereix, es podran afegir noves zones de ritme.
A6: • Dia de descans total: s'assumeix 1 dia/setmana (proposta: diumenge; ajustable segons disponibilitat del nedador).
A7: • Sessions: 4 sessions obligatòries + 1 d'opcional, fetes en ordre (S1-S4 + Opcional). No s'assignen dies fixos, excepte: (a) el test CSS, fixat el dijous, i (b) les setmanes de qualitat, on es recomana situar 2 sessions en dimecres i dissabte.
A8: • Dies de qualitat: Dimecres + Dissabte, aplicats aproximadament 1 de cada 3 setmanes (setmanes 3, 6, 10 i 16), ajustats al calendari de competicions de classe B i C.
A9: • Orquestració de mesocicles: cada mesocicle tanca amb una prova de classe B o C del calendari (Etapa Barceloneta 17/10, Memorial Cuesta 07/11, Gran Premi Marrugat 12/12), que fa de control extern. El macrocicle acaba amb el doble pic de proves A: Campionat Catalunya (16-17/01/2027) i Campeonato España (04-07/02/2027).
A10: • Tests d'avaluació d'assoliment a les setmanes de baixada de rendiment: control extern via competició (setmanes 4, 7 i 12) o test intern de simulacre a ritme objectiu (setmana 16, única setmana de descàrrega sense competició programada).
A11: • Aquest document és una planificació de MESOCICLES I FASES (nivell setmanal). No inclou el detall dia a dia de sèries d'entrenament.
A12: • Test CSS: es repeteix cada 6-8 setmanes (protocol habitual segons metodologies d'entrenament). Programat 3 cops en aquest macrocicle: setmana 1 (línia base, dijous 24/09), setmana 7 (recalibratge previ a M3) i setmana 13 (recalibratge previ al bloc específic M4). No es repeteix a les setmanes 19-20 per no restar frescor abans del doble pic: les zones de M5 s'arrosseguen del test de la setmana 13.
A13: • 5è estil - Subaquàtic: es tracta com a disciplina tècnica pròpia (sortides, viratges i patada subaquàtica/fletxa), amb bloc específic dins la part de Tècnica de cada sessió (vegeu pestanya 'Estructura de sessió').
... A16: • Cris i Pere: com que encara no tenen ritmes A1/A2/A3 propis, les sessions de la setmana 1 s'expressen en esforç percebut (A1 esforç còmode / A2 moderat-alt / A3 alt) en comptes de temps concrets. Es podran passar a temps exactes un cop tinguin el resultat del test CSS.
